Traceback (most recent call last):
  File "semantic_segmentation_playground.py", line 17, in <module>
    semantic_segmentation = pipeline("image-segmentation", "nvidia/segformer-b1-finetuned-cityscapes-1024-1024")
  File "/cluster/home/wueestm/anaconda3/envs/f3loc/lib/python3.8/site-packages/transformers/pipelines/__init__.py", line 895, in pipeline
    framework, model = infer_framework_load_model(
  File "/cluster/home/wueestm/anaconda3/envs/f3loc/lib/python3.8/site-packages/transformers/pipelines/base.py", line 299, in infer_framework_load_model
    raise ValueError(
ValueError: Could not load model nvidia/segformer-b1-finetuned-cityscapes-1024-1024 with any of the following classes: (<class 'transformers.models.auto.modeling_auto.AutoModelForImageSegmentation'>, <class 'transformers.models.auto.modeling_auto.AutoModelForSemanticSegmentation'>, <class 'transformers.models.segformer.modeling_segformer.SegformerForSemanticSegmentation'>). See the original errors:

while loading with AutoModelForImageSegmentation, an error is thrown:
Traceback (most recent call last):
  File "/cluster/home/wueestm/anaconda3/envs/f3loc/lib/python3.8/site-packages/transformers/pipelines/base.py", line 286, in infer_framework_load_model
    model = model_class.from_pretrained(model, **kwargs)
  File "/cluster/home/wueestm/anaconda3/envs/f3loc/lib/python3.8/site-packages/transformers/models/auto/auto_factory.py", line 567, in from_pretrained
    raise ValueError(
ValueError: Unrecognized configuration class <class 'transformers.models.segformer.configuration_segformer.SegformerConfig'> for this kind of AutoModel: AutoModelForImageSegmentation.
Model type should be one of DetrConfig.

while loading with AutoModelForSemanticSegmentation, an error is thrown:
Traceback (most recent call last):
  File "/cluster/home/wueestm/anaconda3/envs/f3loc/lib/python3.8/site-packages/urllib3/connection.py", line 203, in _new_conn
    sock = connection.create_connection(
  File "/cluster/home/wueestm/anaconda3/envs/f3loc/lib/python3.8/site-packages/urllib3/util/connection.py", line 85, in create_connection
    raise err
  File "/cluster/home/wueestm/anaconda3/envs/f3loc/lib/python3.8/site-packages/urllib3/util/connection.py", line 73, in create_connection
    sock.connect(sa)
OSError: [Errno 101] Network is unreachable

The above exception was the direct cause of the following exception:

Traceback (most recent call last):
  File "/cluster/home/wueestm/anaconda3/envs/f3loc/lib/python3.8/site-packages/urllib3/connectionpool.py", line 790, in urlopen
    response = self._make_request(
  File "/cluster/home/wueestm/anaconda3/envs/f3loc/lib/python3.8/site-packages/urllib3/connectionpool.py", line 491, in _make_request
    raise new_e
  File "/cluster/home/wueestm/anaconda3/envs/f3loc/lib/python3.8/site-packages/urllib3/connectionpool.py", line 467, in _make_request
    self._validate_conn(conn)
  File "/cluster/home/wueestm/anaconda3/envs/f3loc/lib/python3.8/site-packages/urllib3/connectionpool.py", line 1096, in _validate_conn
    conn.connect()
  File "/cluster/home/wueestm/anaconda3/envs/f3loc/lib/python3.8/site-packages/urllib3/connection.py", line 611, in connect
    self.sock = sock = self._new_conn()
  File "/cluster/home/wueestm/anaconda3/envs/f3loc/lib/python3.8/site-packages/urllib3/connection.py", line 218, in _new_conn
    raise NewConnectionError(
urllib3.exceptions.NewConnectionError: <urllib3.connection.HTTPSConnection object at 0x146a9268f910>: Failed to establish a new connection: [Errno 101] Network is unreachable

The above exception was the direct cause of the following exception:

Traceback (most recent call last):
  File "/cluster/home/wueestm/anaconda3/envs/f3loc/lib/python3.8/site-packages/requests/adapters.py", line 486, in send
    resp = conn.urlopen(
  File "/cluster/home/wueestm/anaconda3/envs/f3loc/lib/python3.8/site-packages/urllib3/connectionpool.py", line 844, in urlopen
    retries = retries.increment(
  File "/cluster/home/wueestm/anaconda3/envs/f3loc/lib/python3.8/site-packages/urllib3/util/retry.py", line 515, in increment
    raise MaxRetryError(_pool, url, reason) from reason  # type: ignore[arg-type]
urllib3.exceptions.MaxRetryError: HTTPSConnectionPool(host='huggingface.co', port=443): Max retries exceeded with url: /nvidia/segformer-b1-finetuned-cityscapes-1024-1024/resolve/main/model.safetensors (Caused by NewConnectionError('<urllib3.connection.HTTPSConnection object at 0x146a9268f910>: Failed to establish a new connection: [Errno 101] Network is unreachable'))

During handling of the above exception, another exception occurred:

Traceback (most recent call last):
  File "/cluster/home/wueestm/anaconda3/envs/f3loc/lib/python3.8/site-packages/transformers/pipelines/base.py", line 286, in infer_framework_load_model
    model = model_class.from_pretrained(model, **kwargs)
  File "/cluster/home/wueestm/anaconda3/envs/f3loc/lib/python3.8/site-packages/transformers/models/auto/auto_factory.py", line 564, in from_pretrained
    return model_class.from_pretrained(
  File "/cluster/home/wueestm/anaconda3/envs/f3loc/lib/python3.8/site-packages/transformers/modeling_utils.py", line 3594, in from_pretrained
    if not has_file(pretrained_model_name_or_path, safe_weights_name, **has_file_kwargs):
  File "/cluster/home/wueestm/anaconda3/envs/f3loc/lib/python3.8/site-packages/transformers/utils/hub.py", line 655, in has_file
    response = get_session().head(
  File "/cluster/home/wueestm/anaconda3/envs/f3loc/lib/python3.8/site-packages/requests/sessions.py", line 624, in head
    return self.request("HEAD", url, **kwargs)
  File "/cluster/home/wueestm/anaconda3/envs/f3loc/lib/python3.8/site-packages/requests/sessions.py", line 589, in request
    resp = self.send(prep, **send_kwargs)
  File "/cluster/home/wueestm/anaconda3/envs/f3loc/lib/python3.8/site-packages/requests/sessions.py", line 703, in send
    r = adapter.send(request, **kwargs)
  File "/cluster/home/wueestm/anaconda3/envs/f3loc/lib/python3.8/site-packages/huggingface_hub/utils/_http.py", line 66, in send
    return super().send(request, *args, **kwargs)
  File "/cluster/home/wueestm/anaconda3/envs/f3loc/lib/python3.8/site-packages/requests/adapters.py", line 519, in send
    raise ConnectionError(e, request=request)
requests.exceptions.ConnectionError: (MaxRetryError("HTTPSConnectionPool(host='huggingface.co', port=443): Max retries exceeded with url: /nvidia/segformer-b1-finetuned-cityscapes-1024-1024/resolve/main/model.safetensors (Caused by NewConnectionError('<urllib3.connection.HTTPSConnection object at 0x146a9268f910>: Failed to establish a new connection: [Errno 101] Network is unreachable'))"), '(Request ID: b449649e-ebdf-4188-b38b-c02fa8dd43fe)')

while loading with SegformerForSemanticSegmentation, an error is thrown:
Traceback (most recent call last):
  File "/cluster/home/wueestm/anaconda3/envs/f3loc/lib/python3.8/site-packages/urllib3/connection.py", line 203, in _new_conn
    sock = connection.create_connection(
  File "/cluster/home/wueestm/anaconda3/envs/f3loc/lib/python3.8/site-packages/urllib3/util/connection.py", line 85, in create_connection
    raise err
  File "/cluster/home/wueestm/anaconda3/envs/f3loc/lib/python3.8/site-packages/urllib3/util/connection.py", line 73, in create_connection
    sock.connect(sa)
OSError: [Errno 101] Network is unreachable

The above exception was the direct cause of the following exception:

Traceback (most recent call last):
  File "/cluster/home/wueestm/anaconda3/envs/f3loc/lib/python3.8/site-packages/urllib3/connectionpool.py", line 790, in urlopen
    response = self._make_request(
  File "/cluster/home/wueestm/anaconda3/envs/f3loc/lib/python3.8/site-packages/urllib3/connectionpool.py", line 491, in _make_request
    raise new_e
  File "/cluster/home/wueestm/anaconda3/envs/f3loc/lib/python3.8/site-packages/urllib3/connectionpool.py", line 467, in _make_request
    self._validate_conn(conn)
  File "/cluster/home/wueestm/anaconda3/envs/f3loc/lib/python3.8/site-packages/urllib3/connectionpool.py", line 1096, in _validate_conn
    conn.connect()
  File "/cluster/home/wueestm/anaconda3/envs/f3loc/lib/python3.8/site-packages/urllib3/connection.py", line 611, in connect
    self.sock = sock = self._new_conn()
  File "/cluster/home/wueestm/anaconda3/envs/f3loc/lib/python3.8/site-packages/urllib3/connection.py", line 218, in _new_conn
    raise NewConnectionError(
urllib3.exceptions.NewConnectionError: <urllib3.connection.HTTPSConnection object at 0x146a924f2460>: Failed to establish a new connection: [Errno 101] Network is unreachable

The above exception was the direct cause of the following exception:

Traceback (most recent call last):
  File "/cluster/home/wueestm/anaconda3/envs/f3loc/lib/python3.8/site-packages/requests/adapters.py", line 486, in send
    resp = conn.urlopen(
  File "/cluster/home/wueestm/anaconda3/envs/f3loc/lib/python3.8/site-packages/urllib3/connectionpool.py", line 844, in urlopen
    retries = retries.increment(
  File "/cluster/home/wueestm/anaconda3/envs/f3loc/lib/python3.8/site-packages/urllib3/util/retry.py", line 515, in increment
    raise MaxRetryError(_pool, url, reason) from reason  # type: ignore[arg-type]
urllib3.exceptions.MaxRetryError: HTTPSConnectionPool(host='huggingface.co', port=443): Max retries exceeded with url: /nvidia/segformer-b1-finetuned-cityscapes-1024-1024/resolve/main/model.safetensors (Caused by NewConnectionError('<urllib3.connection.HTTPSConnection object at 0x146a924f2460>: Failed to establish a new connection: [Errno 101] Network is unreachable'))

During handling of the above exception, another exception occurred:

Traceback (most recent call last):
  File "/cluster/home/wueestm/anaconda3/envs/f3loc/lib/python3.8/site-packages/transformers/pipelines/base.py", line 286, in infer_framework_load_model
    model = model_class.from_pretrained(model, **kwargs)
  File "/cluster/home/wueestm/anaconda3/envs/f3loc/lib/python3.8/site-packages/transformers/modeling_utils.py", line 3594, in from_pretrained
    if not has_file(pretrained_model_name_or_path, safe_weights_name, **has_file_kwargs):
  File "/cluster/home/wueestm/anaconda3/envs/f3loc/lib/python3.8/site-packages/transformers/utils/hub.py", line 655, in has_file
    response = get_session().head(
  File "/cluster/home/wueestm/anaconda3/envs/f3loc/lib/python3.8/site-packages/requests/sessions.py", line 624, in head
    return self.request("HEAD", url, **kwargs)
  File "/cluster/home/wueestm/anaconda3/envs/f3loc/lib/python3.8/site-packages/requests/sessions.py", line 589, in request
    resp = self.send(prep, **send_kwargs)
  File "/cluster/home/wueestm/anaconda3/envs/f3loc/lib/python3.8/site-packages/requests/sessions.py", line 703, in send
    r = adapter.send(request, **kwargs)
  File "/cluster/home/wueestm/anaconda3/envs/f3loc/lib/python3.8/site-packages/huggingface_hub/utils/_http.py", line 66, in send
    return super().send(request, *args, **kwargs)
  File "/cluster/home/wueestm/anaconda3/envs/f3loc/lib/python3.8/site-packages/requests/adapters.py", line 519, in send
    raise ConnectionError(e, request=request)
requests.exceptions.ConnectionError: (MaxRetryError("HTTPSConnectionPool(host='huggingface.co', port=443): Max retries exceeded with url: /nvidia/segformer-b1-finetuned-cityscapes-1024-1024/resolve/main/model.safetensors (Caused by NewConnectionError('<urllib3.connection.HTTPSConnection object at 0x146a924f2460>: Failed to establish a new connection: [Errno 101] Network is unreachable'))"), '(Request ID: ad39324e-36ec-4683-af95-d81833748041)')



