Traceback (most recent call last):
  File "/cluster/home/wueestm/anaconda3/envs/f3loc/lib/python3.8/site-packages/urllib3/connection.py", line 203, in _new_conn
    sock = connection.create_connection(
  File "/cluster/home/wueestm/anaconda3/envs/f3loc/lib/python3.8/site-packages/urllib3/util/connection.py", line 85, in create_connection
    raise err
  File "/cluster/home/wueestm/anaconda3/envs/f3loc/lib/python3.8/site-packages/urllib3/util/connection.py", line 73, in create_connection
    sock.connect(sa)
OSError: [Errno 101] Network is unreachable

The above exception was the direct cause of the following exception:

Traceback (most recent call last):
  File "/cluster/home/wueestm/anaconda3/envs/f3loc/lib/python3.8/site-packages/urllib3/connectionpool.py", line 790, in urlopen
    response = self._make_request(
  File "/cluster/home/wueestm/anaconda3/envs/f3loc/lib/python3.8/site-packages/urllib3/connectionpool.py", line 491, in _make_request
    raise new_e
  File "/cluster/home/wueestm/anaconda3/envs/f3loc/lib/python3.8/site-packages/urllib3/connectionpool.py", line 467, in _make_request
    self._validate_conn(conn)
  File "/cluster/home/wueestm/anaconda3/envs/f3loc/lib/python3.8/site-packages/urllib3/connectionpool.py", line 1096, in _validate_conn
    conn.connect()
  File "/cluster/home/wueestm/anaconda3/envs/f3loc/lib/python3.8/site-packages/urllib3/connection.py", line 611, in connect
    self.sock = sock = self._new_conn()
  File "/cluster/home/wueestm/anaconda3/envs/f3loc/lib/python3.8/site-packages/urllib3/connection.py", line 218, in _new_conn
    raise NewConnectionError(
urllib3.exceptions.NewConnectionError: <urllib3.connection.HTTPSConnection object at 0x14aea73410a0>: Failed to establish a new connection: [Errno 101] Network is unreachable

The above exception was the direct cause of the following exception:

Traceback (most recent call last):
  File "/cluster/home/wueestm/anaconda3/envs/f3loc/lib/python3.8/site-packages/requests/adapters.py", line 486, in send
    resp = conn.urlopen(
  File "/cluster/home/wueestm/anaconda3/envs/f3loc/lib/python3.8/site-packages/urllib3/connectionpool.py", line 844, in urlopen
    retries = retries.increment(
  File "/cluster/home/wueestm/anaconda3/envs/f3loc/lib/python3.8/site-packages/urllib3/util/retry.py", line 515, in increment
    raise MaxRetryError(_pool, url, reason) from reason  # type: ignore[arg-type]
urllib3.exceptions.MaxRetryError: HTTPSConnectionPool(host='huggingface.co', port=443): Max retries exceeded with url: /datasets/huggingface/documentation-images/resolve/main/transformers/tasks/segmentation_input.jpg (Caused by NewConnectionError('<urllib3.connection.HTTPSConnection object at 0x14aea73410a0>: Failed to establish a new connection: [Errno 101] Network is unreachable'))

During handling of the above exception, another exception occurred:

Traceback (most recent call last):
  File "semantic_segmentation_playground.py", line 14, in <module>
    image = Image.open(requests.get(url, stream=True).raw)
  File "/cluster/home/wueestm/anaconda3/envs/f3loc/lib/python3.8/site-packages/requests/api.py", line 73, in get
    return request("get", url, params=params, **kwargs)
  File "/cluster/home/wueestm/anaconda3/envs/f3loc/lib/python3.8/site-packages/requests/api.py", line 59, in request
    return session.request(method=method, url=url, **kwargs)
  File "/cluster/home/wueestm/anaconda3/envs/f3loc/lib/python3.8/site-packages/requests/sessions.py", line 589, in request
    resp = self.send(prep, **send_kwargs)
  File "/cluster/home/wueestm/anaconda3/envs/f3loc/lib/python3.8/site-packages/requests/sessions.py", line 703, in send
    r = adapter.send(request, **kwargs)
  File "/cluster/home/wueestm/anaconda3/envs/f3loc/lib/python3.8/site-packages/requests/adapters.py", line 519, in send
    raise ConnectionError(e, request=request)
requests.exceptions.ConnectionError: HTTPSConnectionPool(host='huggingface.co', port=443): Max retries exceeded with url: /datasets/huggingface/documentation-images/resolve/main/transformers/tasks/segmentation_input.jpg (Caused by NewConnectionError('<urllib3.connection.HTTPSConnection object at 0x14aea73410a0>: Failed to establish a new connection: [Errno 101] Network is unreachable'))
